<?xml version="1.0"?>
<robot xmlns:xacro="http://www.ros.org/wiki/xacro" name="fanuc200ic5l_w_sg2_macro">
  <xacro:macro name="fanuc200ic5l_w_sg2_description" params="">
      <!-- links: main serial chain -->
      <link name="base_link">
        <visual>
          <origin rpy="0 0 0" xyz="0 0 0"/>
          <geometry>
            <mesh filename="package://fanuc_arm_config/urdf/meshes/visual/base_link.stl"/>
          </geometry>
          <material name="">
            <color rgba="0.23921568627450981 0.23921568627450981 0.23921568627450981 1.0"/>
          </material>
        </visual>
        <collision>
          <origin rpy="0 0 0" xyz="0 0 0"/>
          <geometry>
            <mesh filename="package://fanuc_arm_config/urdf/meshes/collision/base_link.stl"/>
          </geometry>
        </collision>
        <inertial>
          <origin xyz="0 0 0" rpy="0 0 0"/>
          <mass value="20.0"/>
          <inertia ixx="1.0" ixy="0.0" ixz="0.0" iyy="1.0" iyz="0.0" izz="1.0"/>
        </inertial>
      </link>
      <link name="link_1">
        <visual>
          <origin rpy="0 0 0" xyz="0 0 0"/>
          <geometry>
            <mesh filename="package://fanuc_arm_config/urdf/meshes/visual/link_1.stl"/>
          </geometry>
          <material name="">
            <color rgba="0.96 0.76 0.13 1.0"/>
          </material>
        </visual>
        <collision>
          <origin rpy="0 0 0" xyz="0 0 0"/>
          <geometry>
            <mesh filename="package://fanuc_arm_config/urdf/meshes/collision/link_1.stl"/>
          </geometry>
        </collision>
        <inertial>
          <origin xyz="0 0 0" rpy="0 0 0"/>
          <mass value="5.0"/>
          <inertia ixx="0.02" ixy="0.0" ixz="0.0" iyy="0.02" iyz="0.0" izz="0.02"/>
        </inertial>
      </link>
      <link name="link_2">
        <visual>
          <origin rpy="0 0 0" xyz="0 0 0"/>
          <geometry>
            <mesh filename="package://fanuc_arm_config/urdf/meshes/visual/link_2.stl"/>
          </geometry>
          <material name="">
            <color rgba="0.96 0.76 0.13 1.0"/>
          </material>
        </visual>
        <collision>
          <origin rpy="0 0 0" xyz="0 0 0"/>
          <geometry>
            <mesh filename="package://fanuc_arm_config/urdf/meshes/collision/link_2.stl"/>
          </geometry>
        </collision>
        <inertial>
          <origin xyz="0 0 0" rpy="0 0 0"/>
          <mass value="5.0"/>
          <inertia ixx="0.02" ixy="0.0" ixz="0.0" iyy="0.02" iyz="0.0" izz="0.02"/>
        </inertial>
      </link>
      <link name="link_3">
        <visual>
          <origin rpy="0 0 0" xyz="0 0 0"/>
          <geometry>
            <mesh filename="package://fanuc_arm_config/urdf/meshes/visual/link_3.stl"/>
          </geometry>
          <material name="">
            <color rgba="0.96 0.76 0.13 1.0"/>
          </material>
        </visual>
        <collision>
          <origin rpy="0 0 0" xyz="0 0 0"/>
          <geometry>
            <mesh filename="package://fanuc_arm_config/urdf/meshes/collision/link_3.stl"/>
          </geometry>
        </collision>
        <inertial>
          <origin xyz="0 0 0" rpy="0 0 0"/>
          <mass value="3.0"/>
          <inertia ixx="0.01" ixy="0.0" ixz="0.0" iyy="0.01" iyz="0.0" izz="0.01"/>
        </inertial>
      </link>
      <link name="link_4">
        <visual>
          <origin rpy="0 0 0" xyz="0 0 0"/>
          <geometry>
            <mesh filename="package://fanuc_arm_config/urdf/meshes/visual/link_4.stl"/>
          </geometry>
          <material name="">
            <color rgba="0.96 0.76 0.13 1.0"/>
          </material>
        </visual>
        <collision>
          <origin rpy="0 0 0" xyz="0 0 0"/>
          <geometry>
            <mesh filename="package://fanuc_arm_config/urdf/meshes/collision/link_4.stl"/>
          </geometry>
        </collision>
        <inertial>
          <origin xyz="0 0 0" rpy="0 0 0"/>
          <mass value="3.0"/>
          <inertia ixx="0.01" ixy="0.0" ixz="0.0" iyy="0.01" iyz="0.0" izz="0.01"/>
        </inertial>
      </link>
      <link name="link_5">
        <visual>
          <origin rpy="0 0 0" xyz="0 0 0"/>
          <geometry>
            <mesh filename="package://fanuc_arm_config/urdf/meshes/visual/link_5.stl"/>
          </geometry>
          <material name="">
            <color rgba="0.96 0.76 0.13 1.0"/>
          </material>
        </visual>
        <collision>
          <origin rpy="0 0 0" xyz="0 0 0"/>
          <geometry>
            <mesh filename="package://fanuc_arm_config/urdf/meshes/collision/link_5.stl"/>
          </geometry>
        </collision>
        <inertial>
          <origin xyz="0 0 0" rpy="0 0 0"/>
          <mass value="2.0"/>
          <inertia ixx="0.005" ixy="0.0" ixz="0.0" iyy="0.005" iyz="0.0" izz="0.005"/>
        </inertial>
      </link>
      <link name="link_6">
        <visual>
          <origin rpy="0 0 0" xyz="0 0 0"/>
          <geometry>
            <mesh filename="package://fanuc_arm_config/urdf/meshes/visual/link_6.stl"/>
          </geometry>
          <material name="">
            <color rgba="0.15 0.15 0.15 1.0"/>
          </material>
        </visual>
        <collision>
          <origin rpy="0 0 0" xyz="0 0 0"/>
          <geometry>
            <mesh filename="package://fanuc_arm_config/urdf/meshes/collision/link_6.stl"/>
          </geometry>
        </collision>
        <inertial>
          <origin xyz="0 0 0" rpy="0 0 0"/>
          <mass value="2.0"/>
          <inertia ixx="0.005" ixy="0.0" ixz="0.0" iyy="0.005" iyz="0.0" izz="0.005"/>
        </inertial>
      </link>
      <!-- joints: main serial chain -->
      <joint name="joint_1" type="revolute">
        <origin rpy="0 0 0" xyz="0 0 0.330"/>
        <parent link="base_link"/>
        <child link="link_1"/>
        <axis xyz="0 0 1"/>
        <limit effort="150" lower="-2.9671" upper="2.9671" velocity="4.7124"/>
      </joint>
      <joint name="joint_2" type="revolute">
        <origin rpy="0 0 0" xyz="0.075 0 0"/>
        <parent link="link_1"/>
        <child link="link_2"/>
        <axis xyz="0 1 0"/>
        <limit effort="150" lower="-1.5708" upper="2.4435" velocity="4.7124"/>
      </joint>
      <joint name="joint_3" type="revolute">
        <origin rpy="0 0 0" xyz="0 0 0.400"/>
        <parent link="link_2"/>
        <child link="link_3"/>
        <axis xyz="0 -1 0"/>
        <limit effort="150" lower="-2.5831" upper="4.0143" velocity="4.7124"/>
      </joint>
      <joint name="joint_4" type="revolute">
        <origin rpy="0 0 0" xyz="0 0 0.075"/>
        <parent link="link_3"/>
        <child link="link_4"/>
        <axis xyz="-1 0 0"/>
        <limit effort="100" lower="-3.3161" upper="3.3161" velocity="7.8540"/>
      </joint>
      <joint name="joint_5" type="revolute">
        <origin rpy="0 0 0" xyz="0.410 0 0"/>
        <parent link="link_4"/>
        <child link="link_5"/>
        <axis xyz="0 -1 0"/>
        <limit effort="100" lower="-2.0944" upper="2.0944" velocity="7.8540"/>
      </joint>
      <joint name="joint_6" type="revolute">
        <origin rpy="0 0 0" xyz="0.080 0 0"/>
        <parent link="link_5"/>
        <child link="link_6"/>
        <axis xyz="-1 0 0"/>
        <limit effort="50" lower="-6.2832" upper="6.2832" velocity="12.5664"/>
      </joint>
      
      <!-- ROS-Industrial 'flange' frame: attachment point for EEF models -->
      <link name="flange"/>
      <joint name="joint_6-flange" type="fixed">
        <origin rpy="0 0 0" xyz="0 0 0"/>
        <parent link="link_6"/>
        <child link="flange"/>
      </joint>
      <!-- ROS-Industrial 'tool0' frame: all-zeros tool frame -->
      <link name="tool0"/>
      <joint name="link_6-tool0" type="fixed">
        <origin rpy="3.141592653589793 -1.5707963267948966 0" xyz="0 0 0"/>
        <parent link="flange"/>
        <child link="tool0"/>
      </joint>
      <!-- Create a fixed joint with a parameterized name. -->
      <joint name="sg2_joint" type="fixed">
        <!-- The parent link must be read from the robot model it is attached to. -->
        <parent link="tool0"/>
        <child link="sg2"/>
        <!-- The tool is directly attached to the flange. -->
        <origin rpy="0 0 0" xyz="0 0 0"/>
      </joint>
      <link name="sg2">
        <visual>
          <geometry>
            <!-- The path to the visual meshes in the package. -->
            <mesh filename="package://fanuc_arm_config/urdf/meshes/visual/sg2_reduced.stl"/>
          </geometry>
          <material name="">
            <color rgba="0.50 0.50 0.50 1.0"/>
          </material>
        </visual>
        <collision>
          <geometry>
            <!-- The path to the collision meshes in the package. -->
            <mesh filename="package://fanuc_arm_config/urdf/meshes/collision/sg2_collision.stl"/>
          </geometry>
        </collision>
        <inertial>
          <origin xyz="0 0 0" rpy="0 0 0"/>
          <mass value="1.0"/>
          <inertia ixx="0.005" ixy="0.0" ixz="0.0" iyy="0.005" iyz="0.0" izz="0.005"/>
        </inertial>
      </link>
      <!-- TCP frame -->
      <joint name="tcp_joint" type="fixed">
        <origin rpy="0.523599 0.3926991 0" xyz="0.038715737 -0.040901752 0.200745221"/>
        <parent link="sg2"/>
        <child link="tcp"/>
      </joint>
      <link name="tcp"/>
      <!-- Tool D435 Camera frame -->
      <joint name="tool_d435_camera_joint" type="fixed">
        <origin rpy="-1.0472 0.3926991 0" xyz="-0.022037840 0.059268154 0.146839082"/>
        <parent link="sg2"/>
        <child link="tool_d435_camera"/>
      </joint>
      <link name="tool_d435_camera"/>
      <joint name="tool_d435_camera_origin_joint" type="fixed">
        <origin rpy="0 0 1.5708" xyz="0 0 0"/>
        <parent link="tool_d435_camera"/>
        <child link="tool_d435_camera_origin"/>
      </joint>
      <link name="tool_d435_camera_origin"/>
      <!-- Tool D405 Camera frame -->
  <joint name="tool_d405_camera_joint" type="fixed">
    <!-- Aim RGBD optical axis along gripper +Z; roll pi to keep image upright -->
    <origin rpy="3.141592653589793 -1.5708 0" xyz="0.004918226 -0.041728555 0.119150812"/>
    <parent link="sg2"/>
    <child link="tool_d405_camera"/>
  </joint>
      <link name="tool_d405_camera"/>
      <joint name="tool_d405_camera_origin_joint" type="fixed">
        <origin rpy="0 0 1.5708" xyz="0 0 0"/>
        <parent link="tool_d405_camera"/>
        <child link="tool_d405_camera_origin"/>
      </joint>
      <link name="tool_d405_camera_origin"/>
      <!-- force sensor frame -->
      <joint name="force_sensor_joint" type="fixed">
        <origin rpy="0 0 0" xyz="0 0 0.02125"/>
        <parent link="sg2"/>
        <child link="force_sensor"/>
      </joint>
      <link name="force_sensor"/>
      <joint name="force_sensor_origin_joint" type="fixed">
        <origin rpy="0 0 1.5708" xyz="0 0 0"/>
        <parent link="force_sensor"/>
        <child link="force_sensor_origin"/>
      </joint>
      <link name="force_sensor_origin"/>
      
  </xacro:macro>
</robot>
